Traceback (most recent call last):
  File "/home/nedchen/anaconda3/envs/jpbooks/lib/python3.12/site-packages/jupyter_cache/executors/utils.py", line 58, in single_nb_execution
    executenb(
  File "/home/nedchen/anaconda3/envs/jpbooks/lib/python3.12/site-packages/nbclient/client.py", line 1314, in execute
    return NotebookClient(nb=nb, resources=resources, km=km, **kwargs).execute()
           ^^^^^^^^^^^^^^^^^^^^^^^^^^^^^^^^^^^^^^^^^^^^^^^^^^^^^^^^^^^^^^^^^^^^^
  File "/home/nedchen/anaconda3/envs/jpbooks/lib/python3.12/site-packages/jupyter_core/utils/__init__.py", line 165, in wrapped
    return loop.run_until_complete(inner)
           ^^^^^^^^^^^^^^^^^^^^^^^^^^^^^^
  File "/home/nedchen/anaconda3/envs/jpbooks/lib/python3.12/asyncio/base_events.py", line 687, in run_until_complete
    return future.result()
           ^^^^^^^^^^^^^^^
  File "/home/nedchen/anaconda3/envs/jpbooks/lib/python3.12/site-packages/nbclient/client.py", line 709, in async_execute
    await self.async_execute_cell(
  File "/home/nedchen/anaconda3/envs/jpbooks/lib/python3.12/site-packages/nbclient/client.py", line 1062, in async_execute_cell
    await self._check_raise_for_error(cell, cell_index, exec_reply)
  File "/home/nedchen/anaconda3/envs/jpbooks/lib/python3.12/site-packages/nbclient/client.py", line 918, in _check_raise_for_error
    raise CellExecutionError.from_cell_and_msg(cell, exec_reply_content)
nbclient.exceptions.CellExecutionError: An error occurred while executing the following cell:
------------------
sample_meta <- read.csv("../document/case7/sample_metadata_table.tsv",sep = "\t", row.names = 1)
sample_meta
------------------

----- stderr -----
Warning message in file(file, "rt"):
“cannot open file '../document/case7/sample_metadata_table.tsv': No such file or directory”
------------------

Error in file(file, "rt"): cannot open the connection
Traceback:

1. read.table(file = file, header = header, sep = sep, quote = quote, 
 .     dec = dec, fill = fill, comment.char = comment.char, ...)
2. file(file, "rt")
3. .handleSimpleError(function (cnd) 
 . {
 .     watcher$capture_plot_and_output()
 .     cnd <- sanitize_call(cnd)
 .     watcher$push(cnd)
 .     switch(on_error, continue = invokeRestart("eval_continue"), 
 .         stop = invokeRestart("eval_stop"), error = invokeRestart("eval_error", 
 .             cnd))
 . }, "cannot open the connection", base::quote(file(file, "rt")))

